<?xml version="1.0" ?>
<!-- =================================================================================== -->
<!-- |    This document was autogenerated by xacro from umaru.xacro                    | -->
<!-- |    EDITING THIS FILE BY HAND IS NOT RECOMMENDED                                 | -->
<!-- =================================================================================== -->
<robot name="UMARU">
  <material name="black">
    <color rgba="0.25 0.25 0.25 1"/>
  </material>
  <material name="light_gray">
    <color rgba="0.7 0.7 0.7 1"/>
  </material>
  <material name="green">
    <color rgba="0 1 0 1"/>
  </material>
  <link name="base_link"/>
  <link name="odom">
    <origion rpy="0 0 0" xyz="0 0 0"/>
  </link>
  <joint name="odom_joint" type="fixed">
    <parent link="base_link"/>
    <child link="odom"/>
    <origin rpy="0 0 0" xyz="0 0 0"/>
  </joint>
  <link name="body">
    <visual>
      <geometry>
        <mesh filename="package://shikaku_test/meshes/teen_size/Body.stl" scale="0.001 0.001 0.001"/>
      </geometry>
      <origin rpy="1.5707963267948966 0 0" xyz="0.0 0.0 0.0"/>
      <material name="black"/>
    </visual>
    <collision>
      <geometry>
        <mesh filename="package://shikaku_test/meshes/teen_size/Body.stl" scale="0.001 0.001 0.001"/>
      </geometry>
      <origin rpy="1.5707963267948966 0 0" xyz="0.0 0.0 0.0"/>
    </collision>
  </link>
  <joint name="body_joint" type="revolute">
    <parent link="odom"/>
    <child link="body"/>
    <origin rpy="0 0 0" xyz="0 0 0.55"/>
    <limit effort="1000" lower="0" upper="0" velocity="1"/>
  </joint>
  <link name="neck">
    <visual>
      <geometry>
        <mesh filename="package://shikaku_test/meshes/teen_size/Neck.stl" scale="0.001 0.001 0.001"/>
      </geometry>
      <origin rpy="1.5707963267948966 1.5707963267948966 0" xyz="0.0 -0.0184 -0.013000000000000001"/>
      <material name="light_gray"/>
    </visual>
    <collision>
      <geometry>
        <mesh filename="package://shikaku_test/meshes/teen_size/Neck.stl" scale="0.001 0.001 0.001"/>
      </geometry>
      <origin rpy="1.5707963267948966 1.5707963267948966 0" xyz="0.0 -0.0184 -0.013000000000000001"/>
    </collision>
  </link>
  <link name="head">
    <visual>
      <geometry>
        <mesh filename="package://shikaku_test/meshes/teen_size/Head.stl" scale="0.001 0.001 0.001"/>
      </geometry>
      <origin rpy="0 -1.5707963267948966 0" xyz="0.0 0.0 0.0"/>
      <material name="black"/>
    </visual>
    <collision>
      <geometry>
        <mesh filename="package://shikaku_test/meshes/teen_size/Head.stl" scale="0.001 0.001 0.001"/>
      </geometry>
      <origin rpy="0 -1.5707963267948966 0" xyz="0.0 0.0 0.0"/>
    </collision>
  </link>
  <link name="right_shoulder">
    <visual>
      <geometry>
        <mesh filename="package://shikaku_test/meshes/teen_size/Shoulder.stl" scale="0.001 0.001 0.001"/>
      </geometry>
      <origin rpy="0 1.5707963267948966 1.5707963267948966" xyz="0.0 0.0 0.0"/>
      <material name="light_gray"/>
    </visual>
    <collision>
      <geometry>
        <mesh filename="package://shikaku_test/meshes/teen_size/Shoulder.stl" scale="0.001 0.001 0.001"/>
      </geometry>
      <origin rpy="0 1.5707963267948966 1.5707963267948966" xyz="0.0 0.0 0.0"/>
    </collision>
  </link>
  <link name="right_upper_arm">
    <visual>
      <geometry>
        <mesh filename="package://shikaku_test/meshes/teen_size/Upper_Arm.stl" scale="0.001 0.001 0.001"/>
      </geometry>
      <origin rpy="0 1.5707963267948966 0" xyz="0.0 0.034999999999999996 0.006"/>
      <material name="black"/>
    </visual>
    <collision>
      <geometry>
        <mesh filename="package://shikaku_test/meshes/teen_size/Upper_Arm.stl" scale="0.001 0.001 0.001"/>
      </geometry>
      <origin rpy="0 1.5707963267948966 0" xyz="0.0 0.034999999999999996 0.006"/>
    </collision>
  </link>
  <link name="right_forearm">
    <visual>
      <geometry>
        <mesh filename="package://shikaku_test/meshes/teen_size/Forearm.stl" scale="0.001 0.001 0.001"/>
      </geometry>
      <origin rpy="0 1.5707963267948966 1.5707963267948966" xyz="-0.034999999999999996 0.006 0.16000000000000003"/>
      <material name="light_gray"/>
    </visual>
    <collision>
      <geometry>
        <mesh filename="package://shikaku_test/meshes/teen_size/Forearm.stl" scale="0.001 0.001 0.001"/>
      </geometry>
      <origin rpy="0 1.5707963267948966 1.5707963267948966" xyz="-0.034999999999999996 0.006 0.16000000000000003"/>
    </collision>
  </link>
  <link name="left_shoulder">
    <visual>
      <geometry>
        <mesh filename="package://shikaku_test/meshes/teen_size/Shoulder.stl" scale="0.001 0.001 0.001"/>
      </geometry>
      <origin rpy="0 1.5707963267948966 1.5707963267948966" xyz="0.0 0.0 0.0"/>
      <material name="light_gray"/>
    </visual>
    <collision>
      <geometry>
        <mesh filename="package://shikaku_test/meshes/teen_size/Shoulder.stl" scale="0.001 0.001 0.001"/>
      </geometry>
      <origin rpy="0 1.5707963267948966 1.5707963267948966" xyz="0.0 0.0 0.0"/>
    </collision>
  </link>
  <link name="left_upper_arm">
    <visual>
      <geometry>
        <mesh filename="package://shikaku_test/meshes/teen_size/Upper_Arm.stl" scale="0.001 0.001 0.001"/>
      </geometry>
      <origin rpy="0 1.5707963267948966 0" xyz="0.0 0.034999999999999996 0.006"/>
      <material name="black"/>
    </visual>
    <collision>
      <geometry>
        <mesh filename="package://shikaku_test/meshes/teen_size/Upper_Arm.stl" scale="0.001 0.001 0.001"/>
      </geometry>
      <origin rpy="0 1.5707963267948966 0" xyz="0.0 0.034999999999999996 0.006"/>
    </collision>
  </link>
  <link name="left_forearm">
    <visual>
      <geometry>
        <mesh filename="package://shikaku_test/meshes/teen_size/Forearm.stl" scale="0.001 0.001 0.001"/>
      </geometry>
      <origin rpy="0 1.5707963267948966 1.5707963267948966" xyz="-0.034999999999999996 0.006 0.16000000000000003"/>
      <material name="light_gray"/>
    </visual>
    <collision>
      <geometry>
        <mesh filename="package://shikaku_test/meshes/teen_size/Forearm.stl" scale="0.001 0.001 0.001"/>
      </geometry>
      <origin rpy="0 1.5707963267948966 1.5707963267948966" xyz="-0.034999999999999996 0.006 0.16000000000000003"/>
    </collision>
  </link>
  <link name="right_groin">
    <visual>
      <geometry>
        <mesh filename="package://shikaku_test/meshes/teen_size/Groin.stl" scale="0.001 0.001 0.001"/>
      </geometry>
      <origin rpy="-1.5707963267948966 -1.5707963267948966 0" xyz="-0.083 -0.047 -0.010000000000000002"/>
      <material name="light_gray"/>
    </visual>
    <collision>
      <geometry>
        <mesh filename="package://shikaku_test/meshes/teen_size/Groin.stl" scale="0.001 0.001 0.001"/>
      </geometry>
      <origin rpy="-1.5707963267948966 -1.5707963267948966 0" xyz="-0.083 -0.047 -0.010000000000000002"/>
    </collision>
  </link>
  <link name="right_buttock">
    <visual>
      <geometry>
        <mesh filename="package://shikaku_test/meshes/teen_size/Buttock.stl" scale="0.001 0.001 0.001"/>
      </geometry>
      <origin rpy="-1.5707963267948966 0 0" xyz="-0.036 -0.047 0.046000000000000006"/>
      <material name="light_gray"/>
    </visual>
    <collision>
      <geometry>
        <mesh filename="package://shikaku_test/meshes/teen_size/Buttock.stl" scale="0.001 0.001 0.001"/>
      </geometry>
      <origin rpy="-1.5707963267948966 0 0" xyz="-0.036 -0.047 0.046000000000000006"/>
    </collision>
  </link>
  <link name="right_thigh">
    <visual>
      <geometry>
        <mesh filename="package://shikaku_test/meshes/teen_size/Thigh.stl" scale="0.001 0.001 0.001"/>
      </geometry>
      <origin rpy="-1.5707963267948966 0 0" xyz="0.0 0.008 -0.034999999999999996"/>
      <material name="black"/>
    </visual>
    <collision>
      <geometry>
        <mesh filename="package://shikaku_test/meshes/teen_size/Thigh.stl" scale="0.001 0.001 0.001"/>
      </geometry>
      <origin rpy="-1.5707963267948966 0 0" xyz="0.0 0.008 -0.034999999999999996"/>
    </collision>
  </link>
  <link name="right_calf">
    <visual>
      <geometry>
        <mesh filename="package://shikaku_test/meshes/teen_size/Calf.stl" scale="0.001 0.001 0.001"/>
      </geometry>
      <origin rpy="0 -1.5707963267948966 0" xyz="0.026400000000000003 0.014000000000000002 0.038000000000000006"/>
      <material name="light_gray"/>
    </visual>
    <collision>
      <geometry>
        <mesh filename="package://shikaku_test/meshes/teen_size/Calf.stl" scale="0.001 0.001 0.001"/>
      </geometry>
      <origin rpy="0 -1.5707963267948966 0" xyz="0.026400000000000003 0.014000000000000002 0.038000000000000006"/>
    </collision>
  </link>
  <link name="right_heel">
    <visual>
      <geometry>
        <mesh filename="package://shikaku_test/meshes/teen_size/Heel.stl" scale="0.001 0.001 0.001"/>
      </geometry>
      <origin rpy="1.5707963267948966 0 1.5707963267948966" xyz="-0.0478 -0.0104 -0.0456"/>
      <material name="black"/>
    </visual>
    <collision>
      <geometry>
        <mesh filename="package://shikaku_test/meshes/teen_size/Heel.stl" scale="0.001 0.001 0.001"/>
      </geometry>
      <origin rpy="1.5707963267948966 0 1.5707963267948966" xyz="-0.0478 -0.0104 -0.0456"/>
    </collision>
  </link>
  <link name="right_foot">
    <visual>
      <geometry>
        <mesh filename="package://shikaku_test/meshes/teen_size/Right_Foot.stl" scale="0.001 0.001 0.001"/>
      </geometry>
      <origin rpy="1.5707963267948966 0 3.141592653589793" xyz="0.010000000000000002 -0.0478 -0.0456"/>
      <material name="light_gray"/>
    </visual>
    <collision>
      <geometry>
        <mesh filename="package://shikaku_test/meshes/teen_size/Right_Foot.stl" scale="0.001 0.001 0.001"/>
      </geometry>
      <origin rpy="1.5707963267948966 0 3.141592653589793" xyz="0.010000000000000002 -0.0478 -0.0456"/>
    </collision>
  </link>
  <link name="left_groin">
    <visual>
      <geometry>
        <mesh filename="package://shikaku_test/meshes/teen_size/Groin.stl" scale="0.001 0.001 0.001"/>
      </geometry>
      <origin rpy="-1.5707963267948966 -1.5707963267948966 0" xyz="-0.083 -0.047 -0.010000000000000002"/>
      <material name="light_gray"/>
    </visual>
    <collision>
      <geometry>
        <mesh filename="package://shikaku_test/meshes/teen_size/Groin.stl" scale="0.001 0.001 0.001"/>
      </geometry>
      <origin rpy="-1.5707963267948966 -1.5707963267948966 0" xyz="-0.083 -0.047 -0.010000000000000002"/>
    </collision>
  </link>
  <link name="left_buttock">
    <visual>
      <geometry>
        <mesh filename="package://shikaku_test/meshes/teen_size/Buttock.stl" scale="0.001 0.001 0.001"/>
      </geometry>
      <origin rpy="-1.5707963267948966 0 0" xyz="-0.036 -0.047 0.046000000000000006"/>
      <material name="light_gray"/>
    </visual>
    <collision>
      <geometry>
        <mesh filename="package://shikaku_test/meshes/teen_size/Buttock.stl" scale="0.001 0.001 0.001"/>
      </geometry>
      <origin rpy="-1.5707963267948966 0 0" xyz="-0.036 -0.047 0.046000000000000006"/>
    </collision>
  </link>
  <link name="left_thigh">
    <visual>
      <geometry>
        <mesh filename="package://shikaku_test/meshes/teen_size/Thigh.stl" scale="0.001 0.001 0.001"/>
      </geometry>
      <origin rpy="-1.5707963267948966 0 3.141592653589793" xyz="0.0 -0.008 -0.034999999999999996"/>
      <material name="black"/>
    </visual>
    <collision>
      <geometry>
        <mesh filename="package://shikaku_test/meshes/teen_size/Thigh.stl" scale="0.001 0.001 0.001"/>
      </geometry>
      <origin rpy="-1.5707963267948966 0 3.141592653589793" xyz="0.0 -0.008 -0.034999999999999996"/>
    </collision>
  </link>
  <link name="left_calf">
    <visual>
      <geometry>
        <mesh filename="package://shikaku_test/meshes/teen_size/Calf.stl" scale="0.001 0.001 0.001"/>
      </geometry>
      <origin rpy="0 -1.5707963267948966 3.141592653589793" xyz="-0.026400000000000003 -0.014000000000000002 0.038000000000000006"/>
      <material name="light_gray"/>
    </visual>
    <collision>
      <geometry>
        <mesh filename="package://shikaku_test/meshes/teen_size/Calf.stl" scale="0.001 0.001 0.001"/>
      </geometry>
      <origin rpy="0 -1.5707963267948966 3.141592653589793" xyz="-0.026400000000000003 -0.014000000000000002 0.038000000000000006"/>
    </collision>
  </link>
  <link name="left_heel">
    <visual>
      <geometry>
        <mesh filename="package://shikaku_test/meshes/teen_size/Heel.stl" scale="0.001 0.001 0.001"/>
      </geometry>
      <origin rpy="1.5707963267948966 0 -1.5707963267948966" xyz="0.0478 0.0104 -0.0456"/>
      <material name="black"/>
    </visual>
    <collision>
      <geometry>
        <mesh filename="package://shikaku_test/meshes/teen_size/Heel.stl" scale="0.001 0.001 0.001"/>
      </geometry>
      <origin rpy="1.5707963267948966 0 -1.5707963267948966" xyz="0.0478 0.0104 -0.0456"/>
    </collision>
  </link>
  <link name="left_foot">
    <visual>
      <geometry>
        <mesh filename="package://shikaku_test/meshes/teen_size/Left_Foot.stl" scale="0.001 0.001 0.001"/>
      </geometry>
      <origin rpy="1.5707963267948966 0 3.141592653589793" xyz="0.010000000000000002 0.0478 -0.0456"/>
      <material name="light_gray"/>
    </visual>
    <collision>
      <geometry>
        <mesh filename="package://shikaku_test/meshes/teen_size/Left_Foot.stl" scale="0.001 0.001 0.001"/>
      </geometry>
      <origin rpy="1.5707963267948966 0 3.141592653589793" xyz="0.010000000000000002 0.0478 -0.0456"/>
    </collision>
  </link>
  <joint name="right_shoulder_pitch" type="revolute">
    <parent link="body"/>
    <child link="right_shoulder"/>
    <origin rpy="0 0 -1.5707963267948966" xyz="-0.0478 -0.0842 0.015"/>
    <limit effort="1000" lower="-3.141592653589793" upper="3.141592653589793" velocity="1"/>
  </joint>
  <joint name="left_shoulder_pitch" type="revolute">
    <parent link="body"/>
    <child link="left_shoulder"/>
    <origin rpy="0 0 1.5707963267948966" xyz="-0.0478 0.0842 0.015"/>
    <limit effort="1000" lower="-3.141592653589793" upper="3.141592653589793" velocity="1"/>
  </joint>
  <joint name="right_shoulder_roll" type="revolute">
    <parent link="right_shoulder"/>
    <child link="right_upper_arm"/>
    <origin rpy="-0.7853981633974483 0 1.5707963267948966" xyz="0.03 0.0 0.0"/>
    <limit effort="1000" lower="-2.356194490192345" upper="0.7853981633974483" velocity="1"/>
  </joint>
  <joint name="left_shoulder_roll" type="revolute">
    <parent link="left_shoulder"/>
    <child link="left_upper_arm"/>
    <origin rpy="0.7853981633974483 0 -1.5707963267948966" xyz="0.03 0.0 0.0"/>
    <limit effort="1000" lower="-0.7853981633974483" upper="2.356194490192345" velocity="1"/>
  </joint>
  <joint name="right_elbow" type="revolute">
    <parent link="right_upper_arm"/>
    <child link="right_forearm"/>
    <origin rpy="0 0 -1.5707963267948966" xyz="-0.006500000000000001 0.0 -0.15500000000000003"/>
    <limit effort="1000" lower="-2.356194490192345" upper="2.356194490192345" velocity="1"/>
  </joint>
  <joint name="left_elbow" type="revolute">
    <parent link="left_upper_arm"/>
    <child link="left_forearm"/>
    <origin rpy="0 0 1.5707963267948966" xyz="-0.006500000000000001 0.0 -0.15500000000000003"/>
    <limit effort="1000" lower="-2.356194490192345" upper="2.356194490192345" velocity="1"/>
  </joint>
  <joint name="right_hip_yaw" type="revolute">
    <parent link="body"/>
    <child link="right_groin"/>
    <origin rpy="0 -1.5707963267948966 0" xyz="-0.0476 -0.0495 -0.136"/>
    <limit effort="1000" lower="-1.5707963267948966" upper="0.7853981633974483" velocity="1"/>
  </joint>
  <joint name="left_hip_yaw" type="revolute">
    <parent link="body"/>
    <child link="left_groin"/>
    <origin rpy="0 -1.5707963267948966 0" xyz="-0.0476 0.0495 -0.136"/>
    <limit effort="1000" lower="-0.7853981633974483" upper="1.5707963267948966" velocity="1"/>
  </joint>
  <joint name="right_hip_roll" type="revolute">
    <parent link="right_groin"/>
    <child link="right_buttock"/>
    <origin rpy="0 -1.5707963267948966 0" xyz="-0.037 0.0 0.027000000000000003"/>
    <limit effort="1000" lower="-0.7853981633974483" upper="1.5707963267948966" velocity="1"/>
  </joint>
  <joint name="left_hip_roll" type="revolute">
    <parent link="left_groin"/>
    <child link="left_buttock"/>
    <origin rpy="0 -1.5707963267948966 0" xyz="-0.037 0.0 0.027000000000000003"/>
    <limit effort="1000" lower="-1.5707963267948966" upper="0.7853981633974483" velocity="1"/>
  </joint>
  <joint name="right_hip_pitch" type="revolute">
    <parent link="right_buttock"/>
    <child link="right_thigh"/>
    <origin rpy="0 0 1.5707963267948966" xyz="-0.025500000000000002 0.0 0.0005"/>
    <limit effort="1000" lower="-1.9634954084936207" upper="1.1780972450961724" velocity="1"/>
  </joint>
  <joint name="left_hip_pitch" type="revolute">
    <parent link="left_buttock"/>
    <child link="left_thigh"/>
    <origin rpy="0 0 -1.5707963267948966" xyz="-0.025500000000000002 0.0 0.0005"/>
    <limit effort="1000" lower="-1.1780972450961724" upper="1.9634954084936207" velocity="1"/>
  </joint>
  <joint name="right_knee" type="revolute">
    <parent link="right_thigh"/>
    <child link="right_calf"/>
    <origin rpy="0 0 0" xyz="0.0 0.0 0.13799999999999998"/>
    <limit effort="1000" lower="-2.356194490192345" upper="2.356194490192345" velocity="1"/>
  </joint>
  <joint name="left_knee" type="revolute">
    <parent link="left_thigh"/>
    <child link="left_calf"/>
    <origin rpy="0 0 0" xyz="0.0 0.0 0.13799999999999998"/>
    <limit effort="1000" lower="-0.7853981633974483" upper="0.7853981633974483" velocity="1"/>
  </joint>
  <joint name="right_ankle_pitch" type="revolute">
    <parent link="right_calf"/>
    <child link="right_heel"/>
    <origin rpy="0 0 3.141592653589793" xyz="0.0 0.0 0.13799999999999998"/>
    <limit effort="1000" lower="-0.7853981633974483" upper="0.7853981633974483" velocity="1"/>
  </joint>
  <joint name="left_ankle_pitch" type="revolute">
    <parent link="left_calf"/>
    <child link="left_heel"/>
    <origin rpy="0 0 3.141592653589793" xyz="0.0 0.0 0.13799999999999998"/>
    <limit effort="1000" lower="-2.356194490192345" upper="2.356194490192345" velocity="1"/>
  </joint>
  <joint name="right_ankle_roll" type="revolute">
    <parent link="right_heel"/>
    <child link="right_foot"/>
    <origin rpy="0 0 -1.5707963267948966" xyz="0.0 0.0 0.0"/>
    <limit effort="1000" lower="-0.7853981633974483" upper="0.7853981633974483" velocity="1"/>
  </joint>
  <joint name="left_ankle_roll" type="revolute">
    <parent link="left_heel"/>
    <child link="left_foot"/>
    <origin rpy="0 0 1.5707963267948966" xyz="0.0 0.0 0.0"/>
    <limit effort="1000" lower="-0.7853981633974483" upper="0.7853981633974483" velocity="1"/>
  </joint>
  <joint name="neck_yaw" type="revolute">
    <parent link="body"/>
    <child link="neck"/>
    <origin rpy="0 -1.5707963267948966 0" xyz="-0.0184 0.0 0.04000000000000001"/>
    <limit effort="1000" lower="-3.141592653589793" upper="3.141592653589793" velocity="1"/>
  </joint>
  <joint name="neck_pitch" type="revolute">
    <parent link="neck"/>
    <child link="head"/>
    <origin rpy="1.5707963267948966 3.141592653589793 1.5707963267948966" xyz="0.034999999999999996 0.0 0.0"/>
    <limit effort="1000" lower="-1.5707963267948966" upper="0.39269908169872414" velocity="1"/>
  </joint>
  <link name="camera">
    <origion rpy="0 0 0" xyz="0 0 0"/>
  </link>
  <joint name="camera_joint" type="revolute">
    <parent link="head"/>
    <child link="camera"/>
    <origin rpy="-1.5707963267948966 0 0" xyz="0.0 0.020000000000000004 0.04000000000000001"/>
    <limit effort="1000" lower="0" upper="0" velocity="1"/>
  </joint>
  <link name="right_foot_frame">
    <origion rpy="0 0 0" xyz="0 0 0"/>
  </link>
  <joint name="right_foot_joint" type="revolute">
    <parent link="right_foot"/>
    <child link="right_foot_frame"/>
    <origin rpy="0 0 0" xyz="0.0 0.0 0.04000000000000001"/>
    <limit effort="1000" lower="0" upper="0" velocity="1"/>
  </joint>
  <link name="left_foot_frame">
    <origion rpy="0 0 0" xyz="0 0 0"/>
  </link>
  <joint name="left_foot_joint" type="revolute">
    <parent link="left_foot"/>
    <child link="left_foot_frame"/>
    <origin rpy="0 0 0" xyz="0.0 0.0 0.04000000000000001"/>
    <limit effort="1000" lower="0" upper="0" velocity="1"/>
  </joint>
</robot>
